Workbook

Sheet Cost Calculator
A1: Calcu-Buddy MAT142 — Claude API cost model
A2: Edit the yellow cells only. Everything else recalculates.
A4: INPUTS
A5: Students enrolled | B5: 15 | C5: Confirmed: the bottom 20% of the cohort, targeted intervention.
A6: Tutoring sessions per student, per semester | B6: 10 | C6: A session = one sitting with the tutor.
A7: Turns per session | B7: 30 | C7: Raised from 25. Struggling students trigger the hint ladder more often, which adds turns.
A8: Avg student message (tokens) | B8: 30 | C8: Calcu-Buddy invites short answers: a number, a derivative, 'I'm stuck'.
A9: Avg Calcu-Buddy reply (tokens) | B9: 220 | C9: Prompt caps replies at 2-3 sentences + one question; LaTeX inflates the count.
A10: System prompt (tokens) | B10: 8000 | C10: ~5,200 for the Calcu-Buddy prompt + slide-derived curriculum + the student's memory summary.
A11: Cache effectiveness | B11: 0.75 | C11: Share of context served from a warm cache. 5-min cache expires while a student thinks.
A12: USD to INR | B12: 88 | C12: Adjust to the current rate.
A13: End-of-session memory summary ($) | B13: 0.0015 | C13: One cheap Haiku call to write the recap that carries into the next session.
A15: TOKENS PER SESSION
A16: Input tokens if nothing is cached | B16: =$B$7*$B$10 + $B$8*$B$7*($B$7+1)/2 + $B$9*$B$7*($B$7-1)/2 -> 349650 | C16: Every turn resends the whole conversation, so this grows with the square of turn count.
A17: Cache-write tokens | B17: =$B$10 + $B$7*$B$8 + ($B$7-1)*$B$9 -> 15280 | C17: Each new message is written to cache once.
A18: Cache-read tokens | B18: =($B$7-1)*$B$10 + $B$8*($B$7-1)*$B$7/2 + $B$9*($B$7-1)*($B$7-2)/2 -> 334370 | C18: The bulk of input, billed at one tenth of base rate.
A19: Output tokens | B19: =$B$7*$B$9 -> 6600
A20: Conversation size at end of session | B20: =$B$10 + $B$7*$B$8 + $B$7*$B$9 -> 15500 | C20: Well inside the context window — no truncation needed.
A22: COST BY MODEL
A23: Model | B23: $ / session | C23: $ / student / semester | D23: Semester total (USD) | E23: Semester total (INR)
A24: Claude Sonnet 5 | B24: =( $B$11*( $B$17*Pricing!$C$5 + $B$18*Pricing!$D$5 ) + (1-$B$11)*$B$16*Pricing!$B$5 + $B$19*Pricing!$E$5 )/1000000 + $B$13 -> 0.3211305 | C24: =B24*$B$6 -> 3.211305 | D24: =C24*$B$5 -> 48.169575 | E24: =D24*$B$12 -> 4238.9226
A25: Claude Haiku 4.5 | B25: =( $B$11*( $B$17*Pricing!$C$6 + $B$18*Pricing!$D$6 ) + (1-$B$11)*$B$16*Pricing!$B$6 + $B$19*Pricing!$E$6 )/1000000 + $B$13 -> 0.16131525 | C25: =B25*$B$6 -> 1.6131525 | D25: =C25*$B$5 -> 24.197288 | E25: =D25*$B$12 -> 2129.3613
A26: Claude Opus 5 | B26: =( $B$11*( $B$17*Pricing!$C$7 + $B$18*Pricing!$D$7 ) + (1-$B$11)*$B$16*Pricing!$B$7 + $B$19*Pricing!$E$7 )/1000000 + $B$13 -> 0.80057625 | C26: =B26*$B$6 -> 8.0057625 | D26: =C26*$B$5 -> 120.08644 | E26: =D26*$B$12 -> 10567.606
A28: At 15 students the model choice costs little in absolute terms, so Opus 5 is a reasonable call: this cohort needs the strongest possible answer-checking and anxiety handling.
A30: RUNNING COSTS BEYOND THE API (per semester)
A31: Hosting (Vercel Hobby) | B31: 0 | C31: Free tier is sufficient for one class. Pro is $20/month if you outgrow it.
A32: Database (Supabase free tier) | B32: 0 | C32: Free tier covers logins and session memory at this scale.
A33: Domain name | B33: 6 | C33: ~$12/year, so ~$6 per semester. Optional — a vercel.app URL works.
A34: Infrastructure subtotal | B34: =SUM(B31:B33) -> 6
A36: SEMESTER TOTAL (Opus 5 + infrastructure)
A37: Total, USD | B37: =D26+B34 -> 126.08644
A38: Total, INR | B38: =B37*$B$12 -> 11095.606
A39: Cost per student, USD | B39: =B37/$B$5 -> 8.4057625
A41: Legend: yellow cells are yours to edit; green text is pulled from the Pricing tab; black is calculated.
A43: STRESS TEST — what if they use it more than expected?
A44: Scenario | B44: Sessions each | C44: Turns each | D44: Opus 5 semester total (USD) | E44: INR
A45: Light — a few visits before exams | B45: 5 | C45: 20 | D45: =(( $B$11*( ($B$10 + $C$45*$B$8 + ($C$45-1)*$B$9)*Pricing!$C$7 + (($C$45-1)*$B$10 + $B$8*($C$45-1)*$C$45/2 + $B$9*($C$45-1)*($C$45-2)/2)*Pricing!$D$7 ) + (1-$B$11)*($C$45*$B$10 + $B$8*$C$45*($C$45+1)/2 + $B$9*$C$45*($C$45-1)/2)*Pricing!$B$7 + ($C$45*$B$9)*Pricing!$E$7 )/1000000 + $B$13)*$B$45*$B$5 -> 37.858219 | E45: =D45*$B$12 -> 3331.5233
A46: Expected — the planning case | B46: 10 | C46: 30 | D46: =(( $B$11*( ($B$10 + $C$46*$B$8 + ($C$46-1)*$B$9)*Pricing!$C$7 + (($C$46-1)*$B$10 + $B$8*($C$46-1)*$C$46/2 + $B$9*($C$46-1)*($C$46-2)/2)*Pricing!$D$7 ) + (1-$B$11)*($C$46*$B$10 + $B$8*$C$46*($C$46+1)/2 + $B$9*$C$46*($C$46-1)/2)*Pricing!$B$7 + ($C$46*$B$9)*Pricing!$E$7 )/1000000 + $B$13)*$B$46*$B$5 -> 120.08644 | E46: =D46*$B$12 -> 10567.606
A47: Heavy — weekly use all semester | B47: 14 | C47: 40 | D47: =(( $B$11*( ($B$10 + $C$47*$B$8 + ($C$47-1)*$B$9)*Pricing!$C$7 + (($C$47-1)*$B$10 + $B$8*($C$47-1)*$C$47/2 + $B$9*($C$47-1)*($C$47-2)/2)*Pricing!$D$7 ) + (1-$B$11)*($C$47*$B$10 + $B$8*$C$47*($C$47+1)/2 + $B$9*$C$47*($C$47-1)/2)*Pricing!$B$7 + ($C$47*$B$9)*Pricing!$E$7 )/1000000 + $B$13)*$B$47*$B$5 -> 238.77026 | E47: =D47*$B$12 -> 21011.783
A48: Worst case — near-daily reliance | B48: 30 | C48: 50 | D48: =(( $B$11*( ($B$10 + $C$48*$B$8 + ($C$48-1)*$B$9)*Pricing!$C$7 + (($C$48-1)*$B$10 + $B$8*($C$48-1)*$C$48/2 + $B$9*($C$48-1)*($C$48-2)/2)*Pricing!$D$7 ) + (1-$B$11)*($C$48*$B$10 + $B$8*$C$48*($C$48+1)/2 + $B$9*$C$48*($C$48-1)/2)*Pricing!$B$7 + ($C$48*$B$9)*Pricing!$E$7 )/1000000 + $B$13)*$B$48*$B$5 -> 681.32306 | E48: =D48*$B$12 -> 59956.429
...

Sheet Pricing
A1: Claude API pricing (USD per million tokens)
A2: Source: Anthropic pricing docs, retrieved 3 September 2026 — https://platform.claude.com/docs/en/about-claude/pricing
A4: Model | B4: Base input | C4: 5m cache write | D4: Cache read (hit) | E4: Output
A5: Claude Sonnet 5 | B5: 2 | C5: 2.5 | D5: 0.2 | E5: 10
A6: Claude Haiku 4.5 | B6: 1 | C6: 1.25 | D6: 0.1 | E6: 5
A7: Claude Opus 5 | B7: 5 | C7: 6.25 | D7: 0.5 | E7: 25
A9: Cache read is 0.1x base input; a 5-minute cache write is 1.25x base input. Batch API (50% off) does not apply — this is live interactive chat.

Sheet Scenarios
A1: Semester API cost, Opus 5 (USD)
A2: Per-session cost is pulled live from the Cost Calculator tab, so edits there flow through here.
A4: Students \ sessions each | B4: 5 | C4: 10 | D4: 20 | E4: 30
A5: 10 | B5: ='Cost Calculator'!$B$26*10*5 -> 40.028813 | C5: ='Cost Calculator'!$B$26*10*10 -> 80.057625 | D5: ='Cost Calculator'!$B$26*10*20 -> 160.11525 | E5: ='Cost Calculator'!$B$26*10*30 -> 240.17288
A6: 15 | B6: ='Cost Calculator'!$B$26*15*5 -> 60.043219 | C6: ='Cost Calculator'!$B$26*15*10 -> 120.08644 | D6: ='Cost Calculator'!$B$26*15*20 -> 240.17288 | E6: ='Cost Calculator'!$B$26*15*30 -> 360.25931
A7: 20 | B7: ='Cost Calculator'!$B$26*20*5 -> 80.057625 | C7: ='Cost Calculator'!$B$26*20*10 -> 160.11525 | D7: ='Cost Calculator'!$B$26*20*20 -> 320.2305 | E7: ='Cost Calculator'!$B$26*20*30 -> 480.34575
A8: 30 | B8: ='Cost Calculator'!$B$26*30*5 -> 120.08644 | C8: ='Cost Calculator'!$B$26*30*10 -> 240.17288 | D8: ='Cost Calculator'!$B$26*30*20 -> 480.34575 | E8: ='Cost Calculator'!$B$26*30*30 -> 720.51863
A9: 45 | B9: ='Cost Calculator'!$B$26*45*5 -> 180.12966 | C9: ='Cost Calculator'!$B$26*45*10 -> 360.25931 | D9: ='Cost Calculator'!$B$26*45*20 -> 720.51863 | E9: ='Cost Calculator'!$B$26*45*30 -> 1080.7779
A10: 60 | B10: ='Cost Calculator'!$B$26*60*5 -> 240.17288 | C10: ='Cost Calculator'!$B$26*60*10 -> 480.34575 | D10: ='Cost Calculator'!$B$26*60*20 -> 960.6915 | E10: ='Cost Calculator'!$B$26*60*30 -> 1441.0373
A13: Row 2 (15 students) is your planning case. The rest shows what scaling to the full cohort would cost later.

Sheet Assumptions
A1: Where every number came from
A3: System prompt size | B3: The Calcu-Buddy prompt file in your folder is 15,259 characters, which is roughly 5,200 tokens on the current tokenizer. The model adds headroom to 8,000 for the slide-derived curriculum summary and each student's carried-over memory.
A4: Turns per session | B4: 25 turns is a 30-40 minute sitting. Calcu-Buddy's design — short replies, one check question each turn — produces more turns than a typical chatbot, which is why turn count matters more than session length.
A5: Reply length | B5: Raised to 30 for this cohort. Calcu-Buddy's hint ladder (small hint, bigger hint, work the first step, then a full worked example) fires far more often with struggling students, and each rung is a turn.
A6: Cache effectiveness | B6: The 5-minute prompt cache expires while a student sits thinking about a problem. 75% is a deliberately cautious estimate; a chattier session does better, a slow one worse. Set it to 0% to see the true worst case.
A7: Cache blending | B7: An approximation: the model treats the cache-effectiveness figure as the share of context served warm, and bills the remainder at full base-input rates. Real billing is per-turn and slightly more favourable than this.
A8: Memory summary | B8: Session memory needs a short recap written at the end of each session. Costed as one Haiku 4.5 call over a 14k-token conversation producing ~400 tokens.
A9: Batch discount | B9: Not applied. The Batch API's 50% discount requires asynchronous processing; a live tutor cannot use it.
A10: Cohort size | B10: Confirmed at 15 — the bottom 20% of the cohort, as a targeted intervention. Cost scales linearly, so the Scenarios tab shows what opening it to everyone would cost.
A11: Excluded | B11: Your own time, and any cost of an institutional Anthropic account. Anthropic does list academic discounts as available on request, which is worth pursuing before you commit.
A12: Model choice | B12: Opus 5, at your direction. Defensible here: this cohort is the most vulnerable to a tutor that praises a wrong answer or mishandles negative self-talk, and at 15 students the premium over Sonnet is a few tens of dollars a semester.
